{
    "summary": "\nThe force_fallback function is a context manager that temporarily forces a PyTorch operation to use a fallback implementation. The vulnerable line registers a fallback handler for an operation but fails to properly restore the original state if an exception occurs within the context. This is problematic because:\n1. It modifies global state (lowerings dict)\n2. Doesn't guarantee cleanup on exception\n3. Could leave operations permanently using fallback handlers\n4. Breaks the context manager contract of reliable cleanup\n```\n\n```python\nclass TestModel(nn.Module):\n    def __init__(self):\n        super().__init__()\n        self.conv = nn.Conv2d(3, 16, kernel_size=3)\n        \n    def forward(self, x):\n        with force_fallback(aten.convolution.default):\n            # This will use fallback even if exception occurs\n            x = self.conv(x)\n            x = x * 0.5\n            if x.sum() > 0:  # Potential exception point\n                raise ValueError(\"Test error\")\n        return x  # Original lowering not properly restored if exception occurred\n",
    "python_code": "\nclass TestModel(nn.Module):\n    def __init__(self):\n        super().__init__()\n        self.conv = nn.Conv2d(3, 16, kernel_size=3)\n        \n    def forward(self, x):\n        with force_fallback(aten.convolution.default):\n            # This will use fallback even if exception occurs\n            x = self.conv(x)\n            x = x * 0.5\n            if x.sum() > 0:  # Potential exception point\n                raise ValueError(\"Test error\")\n        return x  # Original lowering not properly restored if exception occurred\n"
}